Workbook
Name CGI: 'Cálculos_CGI e Fin'!$P$21
Name Data_de_Nasc: [1]Capa!$P$6
Name DFI: 'Cálculos_CGI e Fin'!$J$33
Name FIN: 'Cálculos_CGI e Fin'!$P$22
Name FIN_TCC: 'Cálculos_CGI e Fin'!$P$25
Name LTV: 'Cálculos_CGI e Fin'!$I$6
Name mensagem: [1]Capa!#REF!
Name mensagem: [1]Capa!#REF!
Name mensagem: [1]Capa!#REF!
Name MIP: 'Cálculos_CGI e Fin'!$J$32
Name obs: 'Cálculos_CGI e Fin'!$K$30
Name PRAZO: 'Cálculos_CGI e Fin'!$J$6
Name PRICE_POS: 'Cálculos_CGI e Fin'!$P$19
Name PRICE_PRE: 'Cálculos_CGI e Fin'!$P$17
Name PRODUTO: 'Cálculos_CGI e Fin'!$D$3
Name SAC_POS: 'Cálculos_CGI e Fin'!$P$20
Name SAC_PRE: 'Cálculos_CGI e Fin'!$P$18
Name SISTEMA_AMORTIZAÇÃO: 'Cálculos_CGI e Fin'!$K$6
Name TAXA: 'Cálculos_CGI e Fin'!$J$22
Name TCC: 'Cálculos_CGI e Fin'!$P$23
Name TIPO_IMÓVEL: 'Cálculos_CGI e Fin'!$I$3
Name VALOR_CREDITO_BRUTO: 'Cálculos_CGI e Fin'!$D$6
Name VALOR_ESTIMADO_IMÓVEL: 'Cálculos_CGI e Fin'!$G$6

Sheet Cálculos_CGI - SAC FIXA
C2: Produto | H2: Tipo Imóvel
C3: Crédito Com Garantia de Imóvel - CGI | H3: Apartamento
C5: Valor do Crédito Bruto | F5: Valor Estimado do Imóvel | H5: LTV | I5: Prazo | J5: Sistema Amortização
C6: 200000 | F6: 500000 | H6: =IFERROR(C6/F6,"") -> 0.4 | I6: 360 | J6: PRICE - FIXA
C8: Cliente | H8: Nascimento | J8: Renda Familiar Min.
C9: < Insira dados do cleinte mais velho> | H9: =T39 -> 29586 | J9: =ROUNDUP(J44/36%,-2) -> 7800
C12: Valores da Operação - Aproximados | J12: %
C13: Valor Principal do Crédito | I13: =C6 -> 200000 | J13: ---
C14: Valor Estimado do Valor do Imóvel | I14: =F6 -> 500000
C15: Valor Total das Despesas acessórias | I15: 3000 | J15: =I15/I13 -> 0.015
C16: Valor Total do IOF no ato da liberação do Crédito (Sem IOF para operaçõees contratadas até Outubro de 2020) | I16: =IF(TODAY()<=1/10/2020,Q39,"0,00") -> 0,00 | J16: =I16/I13 -> 0
C17: Valor Liquido a ser Liberado ao Emitente ou Vendedor | I17: =I13-I15-I16 -> 197000 | J17: =I17/I13 -> 0.985
C18: Prazo da Operação | I18: =I6 -> 360
C19: Taxa Efetiva - Anual | I19: =EFFECT(I21,(I18/12)) -> 0.13941581
C20: Taxa Efetiva - Mensal | I20: =IF(H6<=49.99%,1.09%,1.29%) -> 0.0109
C21: Taxa Nominal - Anual | I21: =I22*12 -> 0.1308
C22: Taxa Nominal - Mensal | I22: =I20 -> 0.0109
C23: Sistema de Amortização | I23: =J6 -> PRICE - FIXA | AR23: SISTEMA | AS23: PRÉ | AT23: PÓS
C24: Data de Vencimento da Primeira Prestação | I24: =TODAY() -> 46058 | AR24: PRICE
C25: Data de Vencimento da Última Prestação | I25: =VLOOKUP(I18,A36:B426,2,0) -> 57015 | AR25: SAC
C26: Valor da Prestação (Amortização + Juros) | I26: =$G$44 -> 2735.5556 | Z26: Controles de despesas
C27: Valor do Prêmio de Seguro MIP (Morte e Invalidez Permanente) | I27: =$H$44 -> 46 | J27: 0.00023 | Z27: TRUE
C28: Valor do Prêmio de Seguro DFI (Danos Físicos ao Imóvel) | I28: =$I$44 -> 20 | J28: 4e-05 | Z28: TRUE
C29: Valor Total da Prestação mensal | I29: =I26+I27+I28 -> 2801.5556 | Z29: TRUE
C30: CET - Custo Efetitvo Total | I30: =EFFECT(RATE(I18,((I26+I27+I28)*-1),I13,,)*12,(240/12)) -> 0.1808534
Z32: 3 | AA32: Parcelas
Z33: 2 | AA33: Amortização
Z35: 1 | AA35: Saldo
N36: Formulas de Cálculo IOF | T36: Formulas de Cálculo Idade | AA36: 3 | AB36: =IF(AA36=1,"Evolução Saldo SAC x Price",IF(AA36=2,"Evolução Amortização SAC x Price","Evolução Parcelas SAC x Price")) -> Evolução Parcelas SAC x Price | AC36: =VLOOKUP(AA36,Z32:AA35,2,0) -> Parcelas | AO36: Amortização da View
AO37: N° Parc. | AP37: Tipo | AQ37: Vencimento | AR37: Sdo. Principal | AS37: Principal | AT37: IOF | AU37: Juros | AV37: Seguro | AW37: Parcela Total
O38: Calculo IOF | S38: Part | T38: Faixa Idade | U38: Idade | V38: Alicota | W38: DFI | X38: % de Comp. Renda | AA38: Parc | AB38: =IF($AA$36=1,VLOOKUP(AA38,$AE$38:$AK$218,6,0),IF($AA$36=2,VLOOKUP(AA38,$AE$38:$AK$218,4,0),VLOOKUP(AA38,$AE$38:$AK$218,2,0))) -> Parcela PRICE | AC38: =IF($AA$36=1,VLOOKUP(AA38,$AE$38:$AK$218,7,0),IF($AA$36=2,VLOOKUP(AA38,$AE$38:$AK$218,5,0),VLOOKUP(AA38,$AE$38:$AK$218,3,0))) -> Parcela SAC | AE38: Parc | AF38: Parcela PRICE | AG38: Parcela SAC | AH38: Amort. PRICE | AI38: Amort. SAC | AJ38: Saldo PRICE | AK38: Saldo SAC | AN38: =AR39-K44 -> 50399.576 | AO38: 1 | AP38: JP | AQ38: 44078 | AR38: 250000 | AS38: 155.98 | AT38: 0 | AU38: 3225 | AV38: 77.5 | AW38: 3458.48
N39: Acima de 12meses | O39: 0.03 | P39: =SUM(O56:O251) -> 3266.6667 | Q39: =SUM(P39:P41) -> 4173.0567 | S39: 1° Part | T39: =[1]Capa!P6 -> 29586 | U39: =IF($T$39="","",INT((TODAY())-$T$39)/365.25) -> 45.097878 | V39: =IF(AND(U39>=S48,U39<S49),U48,IF(AND(U39>=S49,U39<S50),U49,IF(AND(U39>=S50,U39<S51),U50,IF(AND(U39>=S51,U39<S52),U51,IF(AND(U39>=S52,U39<S53),U52,IF(AND(U39>=S53,U39<S54),U53,IF(AND(U39>=S54,U39<S55),U54,IF(AND(U39>=S55,U39<S56),U55,IF(AND(U39>=S56,U39<T56),U56,""))))))))) -> 0.00023 | W39: 4e-05 | AA39: =A44 -> 1 | AB39: =IF($AA$36=1,VLOOKUP(AA39,$AE$38:$AK$218,6,0),IF($AA$36=2,VLOOKUP(AA39,$AE$38:$AK$218,4,0),VLOOKUP(AA39,$AE$38:$AK$218,2,0))) -> 16352.11 | AC39: =IF($AA$36=1,VLOOKUP(AA39,$AE$38:$AK$278,7,0),IF($AA$36=2,VLOOKUP(AA39,$AE$38:$AK$278,5,0),VLOOKUP(AA39,$AE$38:$AK$278,3,0))) -> 2801.5556 | AE39: =AA39 -> 1 | AF39: =IFERROR(VLOOKUP(AE39,[1]Cálculos_PRICE!$A$32:$K$212,10,0),"") -> 16352.11 | AG39: =IFERROR(VLOOKUP(AE39,'Cálculos_CGI - SAC FIXA'!A37:K429,10,0),"") -> 2801.5556 | AH39: =IFERROR(VLOOKUP(AE39,[1]Cálculos_PRICE!$A$32:$K$212,6,0),"") -> 1104.2104 | AI39: =IFERROR(VLOOKUP(AE39,'Cálculos_CGI - SAC FIXA'!A37:K429,6,0),"") -> 555.55556 | AJ39: =IFERROR(VLOOKUP(AE39,[1]Cálculos_PRICE!$A$32:$K$240,11,0),"") -> 998895.79 | AK39: =IFERROR(VLOOKUP(AE39,'Cálculos_CGI - SAC FIXA'!A37:K429,11,0),"") -> 199444.44 | AN39: =AR40-K45 -> 50797.141 | AO39: 2 | AP39: JP | AQ39: 44108 | AR39: 249844.02 | AS39: 157.99 | AT39: 0 | AU39: 3222.99 | AV39: 77.46 | AW39: 3458.44
N40: Valor Financiado | O40: 0.0038 | P40: =ROUNDUP(O40*$C$43,2) -> 760 | S40: 2° Part | AA40: =A45 -> 2 | AB40: =IF($AA$36=1,VLOOKUP(AA40,$AE$38:$AK$218,6,0),IF($AA$36=2,VLOOKUP(AA40,$AE$38:$AK$218,4,0),VLOOKUP(AA40,$AE$38:$AK$218,2,0))) -> 16351.865 | AC40: =IF($AA$36=1,VLOOKUP(AA40,$AE$38:$AK$278,7,0),IF($AA$36=2,VLOOKUP(AA40,$AE$38:$AK$278,5,0),VLOOKUP(AA40,$AE$38:$AK$278,3,0))) -> 2290.7842 | AE40: =AA40 -> 2 | AF40: =IFERROR(VLOOKUP(AE40,[1]Cálculos_PRICE!$A$32:$K$212,10,0),"") -> 16351.865 | AG40: =IFERROR(VLOOKUP(AE40,'Cálculos_CGI - SAC FIXA'!A38:K430,10,0),"") -> 2290.7842 | AH40: =IFERROR(VLOOKUP(AE40,[1]Cálculos_PRICE!$A$32:$K$212,6,0),"") -> 1120.7736 | AI40: =IFERROR(VLOOKUP(AE40,'Cálculos_CGI - SAC FIXA'!A38:K430,6,0),"") -> 555.55556 | AJ40: =IFERROR(VLOOKUP(AE40,[1]Cálculos_PRICE!$A$32:$K$240,11,0),"") -> 997775.02 | AK40: =IFERROR(VLOOKUP(AE40,'Cálculos_CGI - SAC FIXA'!A38:K430,11,0),"") -> 198888.89 | AN40: =AR41-K46 -> 51192.667 | AO40: 3 | AP40: JP | AQ40: 44139 | AR40: 249686.03 | AS40: 160.03 | AT40: 0 | AU40: 3220.95 | AV40: 77.43 | AW40: 3458.41
N41: Até 12 meses | O41: 0.0001118 | P41: =SUM(O44:O55) -> 146.39 | S41: 3° Part | AA41: =A46 -> 3 | AB41: =IF($AA$36=1,VLOOKUP(AA41,$AE$38:$AK$218,6,0),IF($AA$36=2,VLOOKUP(AA41,$AE$38:$AK$218,4,0),VLOOKUP(AA41,$AE$38:$AK$218,2,0))) -> 16351.616 | AC41: =IF($AA$36=1,VLOOKUP(AA41,$AE$38:$AK$278,7,0),IF($AA$36=2,VLOOKUP(AA41,$AE$38:$AK$278,5,0),VLOOKUP(AA41,$AE$38:$AK$278,3,0))) -> 2290.6564 | AE41: =AA41 -> 3 | AF41: =IFERROR(VLOOKUP(AE41,[1]Cálculos_PRICE!$A$32:$K$212,10,0),"") -> 16351.616 | AG41: =IFERROR(VLOOKUP(AE41,'Cálculos_CGI - SAC FIXA'!A39:K431,10,0),"") -> 2290.6564 | AH41: =IFERROR(VLOOKUP(AE41,[1]Cálculos_PRICE!$A$32:$K$212,6,0),"") -> 1137.5852 | AI41: =IFERROR(VLOOKUP(AE41,'Cálculos_CGI - SAC FIXA'!A39:K431,6,0),"") -> 555.55556 | AJ41: =IFERROR(VLOOKUP(AE41,[1]Cálculos_PRICE!$A$32:$K$240,11,0),"") -> 996637.43 | AK41: =IFERROR(VLOOKUP(AE41,'Cálculos_CGI - SAC FIXA'!A39:K431,11,0),"") -> 198333.33 | AN41: =AR42-K47 -> 51586.132 | AO41: 4 | AP41: JP | AQ41: 44169 | AR41: 249526 | AS41: 162.09 | AT41: 0 | AU41: 3218.89 | AV41: 77.39 | AW41: 3458.37
A42: Parc | B42: Vencimento | C42: Saldo Inicial | D42: Juros | E42: Saldo Atualizado | F42: Amortização | G42: Prestação Mensal | H42: MIP | I42: DFI | J42: Prestação Mensal Total | K42: Saldo Devedor | O42: IOF DIÁRIO | P42: DIAS | Q42: DIAS_SOMA | S42: 4° Part | AA42: =A47 -> 4 | AB42: =IF($AA$36=1,VLOOKUP(AA42,$AE$38:$AK$218,6,0),IF($AA$36=2,VLOOKUP(AA42,$AE$38:$AK$218,4,0),VLOOKUP(AA42,$AE$38:$AK$218,2,0))) -> 16351.363 | AC42: =IF($AA$36=1,VLOOKUP(AA42,$AE$38:$AK$278,7,0),IF($AA$36=2,VLOOKUP(AA42,$AE$38:$AK$278,5,0),VLOOKUP(AA42,$AE$38:$AK$278,3,0))) -> 2290.5286 | AE42: =AA42 -> 4 | AF42: =IFERROR(VLOOKUP(AE42,[1]Cálculos_PRICE!$A$32:$K$212,10,0),"") -> 16351.363 | AG42: =IFERROR(VLOOKUP(AE42,'Cálculos_CGI - SAC FIXA'!A40:K432,10,0),"") -> 2290.5286 | AH42: =IFERROR(VLOOKUP(AE42,[1]Cálculos_PRICE!$A$32:$K$212,6,0),"") -> 1154.6489 | AI42: =IFERROR(VLOOKUP(AE42,'Cálculos_CGI - SAC FIXA'!A40:K432,6,0),"") -> 555.55556 | AJ42: =IFERROR(VLOOKUP(AE42,[1]Cálculos_PRICE!$A$32:$K$240,11,0),"") -> 995482.78 | AK42: =IFERROR(VLOOKUP(AE42,'Cálculos_CGI - SAC FIXA'!A40:K432,11,0),"") -> 197777.78 | AN42: =AR43-K48 -> 51977.498 | AO42: 5 | AP42: JP | AQ42: 44200 | AR42: 249363.91 | AS42: 164.19 | AT42: 0 | AU42: 3216.79 | AV42: 77.35 | AW42: 3458.33
A43: 0 | B43: =I24 -> 46058 | C43: =I13 -> 200000 | J43: =I17*-1 -> -197000 | K43: =C43 -> 200000 | S43: 5° Part | AA43: =A48 -> 5 | AB43: =IF($AA$36=1,VLOOKUP(AA43,$AE$38:$AK$218,6,0),IF($AA$36=2,VLOOKUP(AA43,$AE$38:$AK$218,4,0),VLOOKUP(AA43,$AE$38:$AK$218,2,0))) -> 16351.106 | AC43: =IF($AA$36=1,VLOOKUP(AA43,$AE$38:$AK$278,7,0),IF($AA$36=2,VLOOKUP(AA43,$AE$38:$AK$278,5,0),VLOOKUP(AA43,$AE$38:$AK$278,3,0))) -> 2290.4009 | AE43: =AA43 -> 5 | AF43: =IFERROR(VLOOKUP(AE43,[1]Cálculos_PRICE!$A$32:$K$212,10,0),"") -> 16351.106 | AG43: =IFERROR(VLOOKUP(AE43,'Cálculos_CGI - SAC FIXA'!A41:K433,10,0),"") -> 2290.4009 | AH43: =IFERROR(VLOOKUP(AE43,[1]Cálculos_PRICE!$A$32:$K$212,6,0),"") -> 1171.9687 | AI43: =IFERROR(VLOOKUP(AE43,'Cálculos_CGI - SAC FIXA'!A41:K433,6,0),"") -> 555.55556 | AJ43: =IFERROR(VLOOKUP(AE43,[1]Cálculos_PRICE!$A$32:$K$240,11,0),"") -> 994310.81 | AK43: =IFERROR(VLOOKUP(AE43,'Cálculos_CGI - SAC FIXA'!A41:K433,11,0),"") -> 197222.22 | AN43: =AR44-K49 -> 52366.753 | AO43: 6 | AP43: JP | AQ43: 44231 | AR43: 249199.72 | AS43: 166.3 | AT43: 0 | AU43: 3214.68 | AV43: 77.32 | AW43: 3458.3
A44: =IF(AND(A43=0,A43<$I$18),A43+1,0) -> 1 | B44: =IFERROR(IF(A44<=$I$18,DATE(YEAR(B43),MONTH(B43)+1,DAY(B43)),"-"),"") -> 46086 | C44: =IF(A44="","",K43) -> 200000 | D44: =C44*$I$20 -> 2180 | E44: =IFERROR(C44+D44,"") -> 202180 | F44: =$I$13/$I$18 -> 555.55556 | G44: =F44+D44 -> 2735.5556 | H44: =C44*$J$27 -> 46 | I44: =IF(A44="","",IF(K43="","",IF(K43=0,"",$J$28*$I$14))) -> 20 | J44: =IFERROR(SUM(I44+H44+G44),"") -> 2801.5556 | K44: =C44-F44 -> 199444.44 | O44: =ROUNDUP(F44*$O$41*Q44,2) -> 1.74 | P44: =IF($A44<=$I$18,B44-B43,) -> 28 | Q44: =IF($A44<=$I$18,$B44-$B$43,) -> 28 | S44: 6° Part | AA44: =A49 -> 6 | AB44: =IF($AA$36=1,VLOOKUP(AA44,$AE$38:$AK$218,6,0),IF($AA$36=2,VLOOKUP(AA44,$AE$38:$AK$218,4,0),VLOOKUP(AA44,$AE$38:$AK$218,2,0))) -> 16350.845 | AC44: =IF($AA$36=1,VLOOKUP(AA44,$AE$38:$AK$278,7,0),IF($AA$36=2,VLOOKUP(AA44,$AE$38:$AK$278,5,0),VLOOKUP(AA44,$AE$38:$AK$278,3,0))) -> 2290.2731 | AE44: =AA44 -> 6 | AF44: =IFERROR(VLOOKUP(AE44,[1]Cálculos_PRICE!$A$32:$K$212,10,0),"") -> 16350.845 | AG44: =IFERROR(VLOOKUP(AE44,'Cálculos_CGI - SAC FIXA'!A42:K434,10,0),"") -> 2290.2731 | AH44: =IFERROR(VLOOKUP(AE44,[1]Cálculos_PRICE!$A$32:$K$212,6,0),"") -> 1189.5482 | AI44: =IFERROR(VLOOKUP(AE44,'Cálculos_CGI - SAC FIXA'!A42:K434,6,0),"") -> 555.55556 | AJ44: =IFERROR(VLOOKUP(AE44,[1]Cálculos_PRICE!$A$32:$K$240,11,0),"") -> 993121.27 | AK44: =IFERROR(VLOOKUP(AE44,'Cálculos_CGI - SAC FIXA'!A42:K434,11,0),"") -> 196666.67 | AN44: =AR45-K50 -> 52753.859 | AO44: 7 | AP44: JP | AQ44: 44259 | AR44: 249033.42 | AS44: 168.45 | AT44: 0 | AU44: 3212.53 | AV44: 77.28 | AW44: 3458.26
A45: =IF(IF(AND(A44>0,A44<$I$18),A44+1,0)=0,"",IF(AND(A44>0,A44<$I$18),A44+1,0)) -> 2 | B45: =IFERROR(IF(A45<=$I$18,DATE(YEAR($B$44),MONTH($B$44)+A44,DAY($B$44)),"-"),"") -> 46117 | C45: =IF(A45="","",K44) -> 199444.44 | D45: =C45*$I$20 -> 2173.9444 | E45: =IFERROR(C45+D45,"") -> 201618.39 | F45: =$I$13/$I$18 -> 555.55556 | G45: =IF(A45="","",PMT($I$20,$I$18,$C$44)*-1) -> 2224.912 | H45: =C45*$J$27 -> 45.872222 | I45: =IF(A45="","",IF(K44="","",IF(K44=0,"",$J$28*$I$14))) -> 20 | J45: =IFERROR(SUM(I45+H45+G45),"") -> 2290.7842 | K45: =C45-F45 -> 198888.89 | O45: =ROUNDUP(F45*$O$41*Q45,2) -> 3.67 | P45: =IF($A45<=$I$18,B45-B44,) -> 31 | Q45: =IF($A45<=$I$18,$B45-$B$43,) -> 59 | S45: 7° Part | AA45: =A50 -> 7 | AB45: =IF($AA$36=1,VLOOKUP(AA45,$AE$38:$AK$218,6,0),IF($AA$36=2,VLOOKUP(AA45,$AE$38:$AK$218,4,0),VLOOKUP(AA45,$AE$38:$AK$218,2,0))) -> 16350.581 | AC45: =IF($AA$36=1,VLOOKUP(AA45,$AE$38:$AK$278,7,0),IF($AA$36=2,VLOOKUP(AA45,$AE$38:$AK$278,5,0),VLOOKUP(AA45,$AE$38:$AK$278,3,0))) -> 2290.1453 | AE45: =AA45 -> 7 | AF45: =IFERROR(VLOOKUP(AE45,[1]Cálculos_PRICE!$A$32:$K$212,10,0),"") -> 16350.581 | AG45: =IFERROR(VLOOKUP(AE45,'Cálculos_CGI - SAC FIXA'!A43:K435,10,0),"") -> 2290.1453 | AH45: =IFERROR(VLOOKUP(AE45,[1]Cálculos_PRICE!$A$32:$K$212,6,0),"") -> 1207.3914 | AI45: =IFERROR(VLOOKUP(AE45,'Cálculos_CGI - SAC FIXA'!A43:K435,6,0),"") -> 555.55556 | AJ45: =IFERROR(VLOOKUP(AE45,[1]Cálculos_PRICE!$A$32:$K$240,11,0),"") -> 991913.87 | AK45: =IFERROR(VLOOKUP(AE45,'Cálculos_CGI - SAC FIXA'!A43:K435,11,0),"") -> 196111.11 | AN45: =AR46-K51 -> 53138.794 | AO45: 8 | AP45: JP | AQ45: 44290 | AR45: 248864.97 | AS45: 170.62 | AT45: 0 | AU45: 3210.36 | AV45: 77.24 | AW45: 3458.22
A46: =IF(IF(AND(A45>0,A45<$I$18),A45+1,0)=0,"",IF(AND(A45>0,A45<$I$18),A45+1,0)) -> 3 | B46: =IFERROR(IF(A46<=$I$18,DATE(YEAR($B$44),MONTH($B$44)+A45,DAY($B$44)),"-"),"") -> 46147 | C46: =IF(A46="","",K45) -> 198888.89 | D46: =C46*$I$20 -> 2167.8889 | E46: =IFERROR(C46+D46,"") -> 201056.78 | F46: =$I$13/$I$18 -> 555.55556 | G46: =IF(A46="","",PMT($I$20,$I$18,$C$44)*-1) -> 2224.912 | H46: =C46*$J$27 -> 45.744444 | I46: =IF(A46="","",IF(K45="","",IF(K45=0,"",$J$28*$I$14))) -> 20 | J46: =IFERROR(SUM(I46+H46+G46),"") -> 2290.6564 | K46: =C46-F46 -> 198333.33 | O46: =ROUNDUP(F46*$O$41*Q46,2) -> 5.53 | P46: =IF($A46<=$I$18,B46-B45,) -> 30 | Q46: =IF($A46<=$I$18,$B46-$B$43,) -> 89 | S46: 8° Part | AA46: =A51 -> 8 | AB46: =IF($AA$36=1,VLOOKUP(AA46,$AE$38:$AK$218,6,0),IF($AA$36=2,VLOOKUP(AA46,$AE$38:$AK$218,4,0),VLOOKUP(AA46,$AE$38:$AK$218,2,0))) -> 16350.312 | AC46: =IF($AA$36=1,VLOOKUP(AA46,$AE$38:$AK$278,7,0),IF($AA$36=2,VLOOKUP(AA46,$AE$38:$AK$278,5,0),VLOOKUP(AA46,$AE$38:$AK$278,3,0))) -> 2290.0175 | AE46: =AA46 -> 8 | AF46: =IFERROR(VLOOKUP(AE46,[1]Cálculos_PRICE!$A$32:$K$212,10,0),"") -> 16350.312 | AG46: =IFERROR(VLOOKUP(AE46,'Cálculos_CGI - SAC FIXA'!A44:K436,10,0),"") -> 2290.0175 | AH46: =IFERROR(VLOOKUP(AE46,[1]Cálculos_PRICE!$A$32:$K$212,6,0),"") -> 1225.5023 | AI46: =IFERROR(VLOOKUP(AE46,'Cálculos_CGI - SAC FIXA'!A44:K436,6,0),"") -> 555.55556 | AJ46: =IFERROR(VLOOKUP(AE46,[1]Cálculos_PRICE!$A$32:$K$240,11,0),"") -> 990688.37 | AK46: =IFERROR(VLOOKUP(AE46,'Cálculos_CGI - SAC FIXA'!A44:K436,11,0),"") -> 195555.56 | AN46: =AR47-K52 -> 53521.53 | AO46: 9 | AP46: JP | AQ46: 44320 | AR46: 248694.35 | AS46: 172.82 | AT46: 0 | AU46: 3208.16 | AV46: 77.2 | AW46: 3458.18
A47: =IF(IF(AND(A46>0,A46<$I$18),A46+1,0)=0,"",IF(AND(A46>0,A46<$I$18),A46+1,0)) -> 4 | B47: =IFERROR(IF(A47<=$I$18,DATE(YEAR($B$44),MONTH($B$44)+A46,DAY($B$44)),"-"),"") -> 46178 | C47: =IF(A47="","",K46) -> 198333.33 | D47: =C47*$I$20 -> 2161.8333 | E47: =IFERROR(C47+D47,"") -> 200495.17 | F47: =$I$13/$I$18 -> 555.55556 | G47: =IF(A47="","",PMT($I$20,$I$18,$C$44)*-1) -> 2224.912 | H47: =C47*$J$27 -> 45.616667 | I47: =IF(A47="","",IF(K46="","",IF(K46=0,"",$J$28*$I$14))) -> 20 | J47: =IFERROR(SUM(I47+H47+G47),"") -> 2290.5286 | K47: =C47-F47 -> 197777.78 | O47: =ROUNDUP(F47*$O$41*Q47,2) -> 7.46 | P47: =IF($A47<=$I$18,B47-B46,) -> 31 | Q47: =IF($A47<=$I$18,$B47-$B$43,) -> 120 | S47: Faixa Idade | U47: Alicota | V47: DFI | AA47: =A52 -> 9 | AB47: =IF($AA$36=1,VLOOKUP(AA47,$AE$38:$AK$218,6,0),IF($AA$36=2,VLOOKUP(AA47,$AE$38:$AK$218,4,0),VLOOKUP(AA47,$AE$38:$AK$218,2,0))) -> 16350.039 | AC47: =IF($AA$36=1,VLOOKUP(AA47,$AE$38:$AK$278,7,0),IF($AA$36=2,VLOOKUP(AA47,$AE$38:$AK$278,5,0),VLOOKUP(AA47,$AE$38:$AK$278,3,0))) -> 2289.8897 | AE47: =AA47 -> 9 | AF47: =IFERROR(VLOOKUP(AE47,[1]Cálculos_PRICE!$A$32:$K$212,10,0),"") -> 16350.039 | AG47: =IFERROR(VLOOKUP(AE47,'Cálculos_CGI - SAC FIXA'!A45:K437,10,0),"") -> 2289.8897 | AH47: =IFERROR(VLOOKUP(AE47,[1]Cálculos_PRICE!$A$32:$K$212,6,0),"") -> 1243.8848 | AI47: =IFERROR(VLOOKUP(AE47,'Cálculos_CGI - SAC FIXA'!A45:K437,6,0),"") -> 555.55556 | AJ47: =IFERROR(VLOOKUP(AE47,[1]Cálculos_PRICE!$A$32:$K$240,11,0),"") -> 989444.49 | AK47: =IFERROR(VLOOKUP(AE47,'Cálculos_CGI - SAC FIXA'!A45:K437,11,0),"") -> 195000 | AN47: =AR48-K53 -> 53902.036 | AO47: 10 | AP47: JP | AQ47: 44351 | AR47: 248521.53 | AS47: 175.05 | AT47: 0 | AU47: 3205.93 | AV47: 77.16 | AW47: 3458.14
...

Sheet Cálculos_CGI e Fin
D2: Produto | I2: Tipo Imóvel
D3: Crédito Com Garantia de Imóvel - CGI | I3: Loja Comercial
D5: Valor do Crédito Bruto | G5: Valor Estimado do Imóvel | I5: LTV | J5: Prazo | K5: Sistema Amortização
D6: 1000000 | G6: 3000000 | I6: =IFERROR(D6/G6,"") -> 0.33333333 | J6: 240 | K6: PRICE
D8: Carencia em meses | F8: Nome cliente | I8: Nascimento | J8: Seguradora | K8: Renda Familiar Min.
D9: 3 | F9: - | I9: 27368 | J9: EXCELSIOR | K9: =IF(D9>0,VLOOKUP(D9+1,B58:K299,10,0)/36%,VLOOKUP(D9+1,B58:K299,10,0)/36%) -> 39915.199
D14: =IF(J16="","LTV Máximo ou Condição de Negócio fora da Politica de Crédito da Instuição Financeira","")
D15: Valores da Operação | K15: %
D16: Valor Principal do Crédito | J16: =IF( I9="","",VALOR_CREDITO_BRUTO) -> 1000000 | K16: --- | P16: LTV | Q16: 49.99% | R16: 0.6 | S16: 0.7
D17: Valor Estimado do Valor do Imóvel | J17: =IF(J16="","",G6) -> 3000000 | P17: PRICE | Q17: 0.0109 | R17: 0.0109 | S17: 0.0109
D18: Valor Total das Despesas acessórias | J18: =IF(J16="","",IF(J6="",0,3980+3450)) -> 7430 | K18: =IFERROR(IF(J6="",0,J18/J16),"") -> 0.00743 | P18: SAC | Q18: 0.0109 | R18: 0.0109 | S18: 0.0109
D19: Valor Total do IOF no ato da liberação do Crédito | J19: 0 | K19: =IF(J16="","",IFERROR(J19/J16,0)) -> 0 | P19: PRICE | Q19: 0.0099 | R19: 0.0099 | S19: 0.0099
D20: Valor Liquido a ser Liberado ao Emitente ou Vendedor | J20: =IFERROR(J16-J18-J19,"") -> 992570 | K20: =IF(J16="","",IFERROR(J20/J16,0)) -> 0.99257 | P20: SAC | Q20: 0.0099 | R20: 0.0099 | S20: 0.0099
D21: Prazo da Operação | J21: =IF(J16="","",J6) -> 240 | P21: Crédito Com Garantia de Imóvel - CGI
D22: Taxa Nominal - Mensal | J22: 0.0129 | P22: Financiamento Imobiliário - Aquisição
D23: Taxa Nominal - Anual | J23: =IFERROR(J22*12,"") -> 0.1548 | P23: Terreno Com Construção Concluída - TCC
D24: Taxa Efetiva - Mensal | K24: 0.0129
D25: Taxa Efetiva - Anual | J25: =(1+(TAXA))^12-1 -> 0.16626933 | P25: Financiamento Imobiliário - Aquisição TCC
D26: Sistema de Amortização | J26: =SISTEMA_AMORTIZAÇÃO -> PRICE
D27: Data de Vencimento da Primeira Prestação | J27: =VLOOKUP(B60,B58:C299,2,0) -> 46086
D28: Data de Vencimento da Última Prestação | J28: =IFERROR(VLOOKUP(J21,B41:C428,2,0),"") -> 53363
D29: =IF(D9>0,"Valor do prêmio de Seguro - 1ª Prestação (MIP + DFI)","Valor da Prestação (Amortização + Juros)") -> Valor do prêmio de Seguro - 1ª Prestação (MIP + DFI) | J29: =IF(D9>0,SUM(I60:J60),IF(D9>0,VLOOKUP(D9+1,$B$60:$H$72,7,0),IF(J16="","",IF(SISTEMA_AMORTIZAÇÃO=PRICE_PRE,(PMT(TAXA,PRAZO,VALOR_CREDITO_BRUTO)*-1), IF(SISTEMA_AMORTIZAÇÃO=PRICE_POS,(PMT(TAXA,PRAZO,VALOR_CREDITO_BRUTO)*-1), IF(SISTEMA_AMORTIZAÇÃO=SAC_PRE,(VALOR_CREDITO_BRUTO/PRAZO)+(VALOR_CREDITO_BRUTO*TAXA), IF(SISTEMA_AMORTIZAÇÃO=SAC_POS,(VALOR_CREDITO_BRUTO/PRAZO)+(VALOR_CREDITO_BRUTO*TAXA)))))))) -> 564
D30: =IF(D9>0,"Valor Total da Prestação mensal - posterior ao período de carência (Amortização + Juros + MIP + DFI)","Valor Total da Prestação mensal (Amortização + Juros + MIP + DFI)") -> Valor Total da Prestação mensal - posterior ao período de carência (Amortização + Juros + MIP + DFI) | J30: =IF(D9>0,VLOOKUP(D9+1,B60:K72,10,0),IF(J16="","",IFERROR(J29+J32+J33,0))) -> 14369.471 | K30: =IF(K31="","","Observação") -> Observação
D31: =IF(D9>0,"Data de Vencimento da 1ª Prestação mensal posterior periódo de Carência","Data de Vencimento da 1ª Prestação mensal sem Carência") -> Data de Vencimento da 1ª Prestação mensal posterior periódo de Carência | J31: =VLOOKUP(D9+1,B58:C299,2,0) -> 46178 | K31: =IF( I9="","Pendente data de Nascimento", IF( AND( J9="Zurich", ((TODAY()-I9)/365.25)>=65, VALOR_CREDITO_BRUTO>=4000000 ), "Necessário DPS", IF( AND( J9="Zurich", ((TODAY()-I9)/365.25)>65, ((TODAY()-I9)/365.25)<=75, VALOR_CREDITO_BRUTO>=2500000 ), "Necessário DPS", IF( AND( J9="Zurich", ((TODAY()-I9)/365.25)>75, VALOR_CREDITO_BRUTO>=1000000 ), "Necessário DPS", IF( AND( J9="Zurich", VALOR_CREDITO_BRUTO>4000000 ), "Necessário DPS", IF( AND( J9="Excelsior", OR( VALOR_ESTIMADO_IMÓVEL>2300000, VALOR_CREDITO_BRUTO>2300000 ) ), "Máximo permitido é de R$ 2.3MM", IF( AND( ((TODAY()-I9)/365.25)>=55, J9="Excelsior", OR( VALOR_CREDITO_BRUTO>=1000000, VALOR_ESTIMADO_IMÓVEL>=1000000 ) ), "Necessário DPS", IF( AND( ((TODAY()-I9)/365.25)>=55, J9="Excelsior", OR( VALOR_ESTIMADO_IMÓVEL>2300000, VALOR_CREDITO_BRUTO>2300000 ) ), "Necessário DPS e Máximo permitido é de R$ 2.3MM", IF( AND( ((TODAY()-I9)/365.25)<55, J9="Excelsior", VALOR_CREDITO_BRUTO<1000000, VALOR_ESTIMADO_IMÓVEL<=1000000 ), "", "" ) ) ) ) ) ) ) )) -> Máximo permitido é de R$ 2.3MM
D32: =IF(D9>0,"Valor do Prêmio de Seguro MIP (Morte e Invalidez Permanente) 1ª Prestação","Valor do Prêmio de Seguro MIP (Morte e Invalidez Permanente)") -> Valor do Prêmio de Seguro MIP (Morte e Invalidez Permanente) 1ª Prestação | J32: =$I$60 -> 342 | K32: =IF(AND(VALOR_CREDITO_BRUTO>10000000,J9="ZURICH"),"0,017100%",IF(J9="EXCELSIOR","0,0171%","0,017100%")) -> 0,0171%
D33: Valor do Prêmio de Seguro DFI (Danos Físicos ao Imóvel) 1ª Prestação | J33: =$J$60 -> 222 | K33: =IF(AND(VALOR_ESTIMADO_IMÓVEL>10000000,J9="ZURICH"),"0,003900%",IF(J9="EXCELSIOR","0,0037%","0,003000%")) -> 0,0037%
D35: CET - Custo Efetitvo Total | J35: =AG424 -> 0.17187437
P41: Formulas de Cálculo IOF | V41: Formulas de Cálculo Idade
Q43: Calculo IOF | U43: Part | V43: Faixa Idade | W43: Idade | X43: Alicota | Y43: DFI | Z43: % de Comp. Renda
P44: Acima de 12meses | Q44: 0.03 | R44: =SUM(Q72:Q419) -> 30984.079 | S44: =SUM(R44:R46) -> 34912.599 | U44: 1° Part | V44: =[1]Capa!P6 -> 29586 | W44: =IF($V$44="","",INT((TODAY())-$V$44)/365.25) -> 45.097878 | X44: =IF(AND(W44>=U64,W44<U65),W64,IF(AND(W44>=U65,W44<U66),W65,IF(AND(W44>=U66,W44<U67),W66,IF(AND(W44>=U67,W44<U68),W67,IF(AND(W44>=U68,W44<U69),W68,IF(AND(W44>=U69,W44<U70),W69,IF(AND(W44>=U70,W44<U71),W70,IF(AND(W44>=U71,W44<U72),W71,IF(AND(W44>=U72,W44<V72),W72,""))))))))) -> 0.00023 | Y44: 4e-05
P45: Valor Financiado | Q45: 0.0038 | R45: =ROUNDUP(Q45*$D$59,2) -> 3800 | U45: 2° Part
P46: Até 12 meses | Q46: 8.2e-05 | R46: =SUM(Q60:Q71) -> 128.52 | U46: 3° Part
D47: Valores Meramente ilustrativos para efeitos de Simulação Inicial
D48: Não Representa - Aprovação de Crédito
D49: A planilha definitiva será enviada posteriormente por ocasião da formalização da operação do Agente Financeiro
B58: Parc | C58: Vencimento | D58: Saldo Inicial | E58: Juros | F58: Saldo Atualizado | G58: Amortização | H58: Prestação Mensal | I58: MIP Morte Invalidez Permanente | J58: DFI Danos Físico do Imóvel | K58: Prestação Mensal Total | L58: Saldo Devedor | N58: =IF(D9>0,"LTV Saldo Carência","") -> LTV Saldo Carência | Q58: IOF DIÁRIO | R58: DIAS | S58: DIAS_SOMA | U58: 4° Part | AC58: TAXA JUROS | AF58: CET s/seguro | AG58: CET c/seguro
B59: 0 | C59: =TODAY() -> 46058 | D59: =J16 -> 1000000 | H59: =-D59 -> -1000000 | K59: =J20*-1 -> -992570 | L59: =D59 -> 1000000 | U59: 5° Part | AC59: 0 | AD59: =J16*-1 -> -1000000 | AE59: =C59 -> 46058 | AF59: =J20*-1 -> -992570 | AG59: =AF59 -> -992570
A60: =J21 -> 240 | B60: =IF(AND(B59=0,B59<$J$21),B59+1,0) -> 1 | C60: =IFERROR(IF(B60<=$J$21,DATE(YEAR(C59),MONTH(C59)+1,DAY(C59)),""),"") -> 46086 | D60: =IF(B60="","",L59) -> 1000000 | E60: =IFERROR((D60*J22),"") -> 12900 | F60: =IFERROR((D60+E60),"") -> 1012900 | G60: =IF($D$9>=B60,0,IFERROR(IF(C60="","",IF(SISTEMA_AMORTIZAÇÃO=PRICE_PRE,H60-E60, IF(SISTEMA_AMORTIZAÇÃO=SAC_PRE,D60/A60, IF(SISTEMA_AMORTIZAÇÃO=SAC_POS,D60/A60)))),"")) -> 0 | H60: =IF(D9>0,0,IF(J16="","",IF(SISTEMA_AMORTIZAÇÃO=PRICE_PRE,(PMT(TAXA,A60,-$D60,)), IF(SISTEMA_AMORTIZAÇÃO=PRICE_POS,(PMT(TAXA,A60,$D60)*-1), IF(SISTEMA_AMORTIZAÇÃO=SAC_PRE,(D60/A60)+(D60*TAXA), IF(SISTEMA_AMORTIZAÇÃO=SAC_POS,(D60/A60)+(D60*TAXA))))))) -> 0 | I60: =IFERROR(D60*$K$32,"")*2 -> 342 | J60: =IF(B60="","",IF(L59="","",IF(L59=0,"",$K$33*$J$17)))*2 -> 222 | K60: =IFERROR(SUM(J60+I60+H60),"") -> 564 | L60: =IF(D9>0,SUM(D60:E60),IFERROR(D60-G60,"")) -> 1012900 | N60: =IF($D$9>=B60,L60/$J$17,"") -> 0.33763333 | Q60: =ROUNDUP(G60*$Q$46*S60,2) -> 0 | R60: =IF($B60<=$J$21,C60-C59,) -> 28 | S60: =IF($B60<=$J$21,$C60-$C$59,) -> 28 | U60: 6° Part | AC60: 30 | AD60: =IF(H60="",0,H60) -> 0 | AE60: =IF(C60="",0,C60) -> 46086 | AF60: =IF(AD60="",0,AD60) -> 0 | AG60: =IF(K60="",0,K60) -> 564
A61: =IFERROR(IF(A60-1<1,"",A60-1),"") -> 239 | B61: =IF(IF(AND(B60>0,B60<$J$21),B60+1,0)=0,"",IF(AND(B60>0,B60<$J$21),B60+1,0)) -> 2 | C61: =IFERROR(IF(B61<=$J$21,DATE(YEAR(C60),MONTH(C60)+1,DAY(C60)),""),"") -> 46117 | D61: =IF(B61="","",L60) -> 1012900 | E61: =IFERROR(D61*TAXA,"") -> 13066.41 | F61: =IFERROR(D61+E61,"") -> 1025966.4 | G61: =IF($D$9>=B61,0,IFERROR(IF(C61="","",IF(SISTEMA_AMORTIZAÇÃO=PRICE_PRE,H61-E61, IF(SISTEMA_AMORTIZAÇÃO=SAC_PRE,D61/A61, IF(SISTEMA_AMORTIZAÇÃO=SAC_POS,D61/A61)))),"")) -> 0 | H61: =IF($D$9>=B61,0,IF(D61="","", IF(SISTEMA_AMORTIZAÇÃO=PRICE_PRE,(PMT(TAXA,A61,$D61,)*-1), IF(SISTEMA_AMORTIZAÇÃO=SAC_POS,(D61/A61)+(D61*TAXA))))) -> 0 | I61: =IFERROR(D61*$K$32,"") -> 173.2059 | J61: =IF(B61="","",IF(L60="","",IF(L60=0,"",$K$33*$J$17))) -> 111 | K61: =IFERROR(SUM(J61+I61+H61),"") -> 284.2059 | L61: =IF($D$9>=B61,SUM(D61:E61),IFERROR(D61-G61,"")) -> 1025966.4 | N61: =IF($D$9>=B61,L61/$J$17,"") -> 0.3419888 | Q61: =ROUNDUP(G61*$Q$46*S61,2) -> 0 | R61: =IF($B61<=$J$21,C61-C60,) -> 31 | S61: =IF($B61<=$J$21,$C61-$C$59,) -> 59 | U61: 7° Part | AC61: 60 | AD61: =IF(H61="",0,H61) -> 0 | AE61: =IF(C61="",0,C61) -> 46117 | AF61: =IF(AD61="",0,AD61) -> 0 | AG61: =IF(K61="",0,K61) -> 284.2059
A62: =IFERROR(IF(A61-1<1,"",A61-1),"") -> 238 | B62: =IF(IF(AND(B61>0,B61<$J$21),B61+1,0)=0,"",IF(AND(B61>0,B61<$J$21),B61+1,0)) -> 3 | C62: =IFERROR(IF(B62<=$J$21,DATE(YEAR(C61),MONTH(C61)+1,DAY(C61)),""),"") -> 46147 | D62: =IF(B62="","",L61) -> 1025966.4 | E62: =IFERROR(D62*TAXA,"") -> 13234.967 | F62: =IFERROR(D62+E62,"") -> 1039201.4 | G62: =IF($D$9>=B62,0,IFERROR(IF(C62="","",IF(SISTEMA_AMORTIZAÇÃO=PRICE_PRE,H62-E62, IF(SISTEMA_AMORTIZAÇÃO=SAC_PRE,D62/A62, IF(SISTEMA_AMORTIZAÇÃO=SAC_POS,D62/A62)))),"")) -> 0 | H62: =IF($D$9>=B62,0,IF(D62="","", IF(SISTEMA_AMORTIZAÇÃO=PRICE_PRE,(PMT(TAXA,A62,$D62,)*-1), IF(SISTEMA_AMORTIZAÇÃO=SAC_POS,(D62/A62)+(D62*TAXA))))) -> 0 | I62: =IFERROR(D62*$K$32,"") -> 175.44026 | J62: =IF(B62="","",IF(L61="","",IF(L61=0,"",$K$33*$J$17))) -> 111 | K62: =IFERROR(SUM(J62+I62+H62),"") -> 286.44026 | L62: =IF($D$9>=B62,SUM(D62:E62),IFERROR(D62-G62,"")) -> 1039201.4 | N62: =IF($D$9>=B62,L62/$J$17,"") -> 0.34640046 | Q62: =ROUNDUP(G62*$Q$46*S62,2) -> 0 | R62: =IF($B62<=$J$21,C62-C61,) -> 30 | S62: =IF($B62<=$J$21,$C62-$C$59,) -> 89 | U62: 8° Part | AC62: 90 | AD62: =IF(H62="",0,H62) -> 0 | AE62: =IF(C62="",0,C62) -> 46147 | AF62: =IF(AD62="",0,AD62) -> 0 | AG62: =IF(K62="",0,K62) -> 286.44026
...

Sheet Planilha2
F5: taxa juros | H5: CET s/seguro | I5: CET c/seguro
E6: 0 | F6: -2000000 | G6: 44645 | H6: -1919423.8 | I6: =H6 -> -1919423.8
E7: 30 | F7: 0 | G7: 44676 | H7: =F7 -> 0 | I7: 1240
E8: 60 | F8: 0 | G8: 44706 | H8: =F8 -> 0 | I8: 625.934
E9: 90 | F9: 0 | G9: 44737 | H9: =F9 -> 0 | I9: 631.94455
E10: 120 | F10: 0 | G10: 44767 | H10: =F10 -> 0 | I10: 638.03263
E11: 150 | F11: 0 | G11: 44798 | H11: =F11 -> 0 | I11: 644.19925
E12: 180 | F12: 0 | G12: 44829 | H12: =F12 -> 0 | I12: 650.44542
E13: 210 | F13: 0 | G13: 44859 | H13: =F13 -> 0 | I13: 656.77217
E14: 240 | F14: 0 | G14: 44890 | H14: =F14 -> 0 | I14: 663.18053
E15: 270 | F15: 0 | G15: 44920 | H15: =F15 -> 0 | I15: 669.67156
E16: 300 | F16: 0 | G16: 44951 | H16: =F16 -> 0 | I16: 676.24632
E17: 330 | F17: 0 | G17: 44982 | H17: =F17 -> 0 | I17: 682.9059
E18: 360 | F18: 0 | G18: 45010 | H18: =F18 -> 0 | I18: 689.65139
... E246: 7200 | F246: 31800.79 | G246: 51950 | H246: =F246 -> 31800.79 | I246: 31968.008
F248: =XIRR(F6:F246,E6:E246,0)+1 -> 1.1687635 | H248: =XIRR(H6:H246,G6:G246,0)+1 -> 1.1735778 | I248: =XIRR(I6:I246,G6:G246,0)+1 -> 1.1780365
F249: =(F248)^(30/365)-1 -> 0.012900001 | H249: =(H248)^(30/365)-1 -> 0.013242286 | I249: =(I248)^(30/365)-1 -> 0.013558135
H251: =H248-1 -> 0.17357782 | I251: =I248-1 -> 0.17803649
H252: cet | I252: cet total

Sheet Planilha1
A3: Crédito Com Garantia de Imóvel - CGI
A4: Financiamento Imobiliário - Aquisição
A5: Terreno Com Construção Concluída - TCC

Sheet CAPA
E15: SIMULAÇÃO
B24: Crédito Com Garantia de Imóvel PRICE - FIXA (Parcela Sem Correção por IPCA) | P24: Financiamento Imobiliário SAC - FIXA (Parcela sem Correção por IPCA)
B41: Crédito Com Garantia de Imóvel PRICE - FIXA (Parcela Sem Correção por IPCA) | P41: Financiamento Imobiliário SAC - FIXA (Parcela sem Correção por IPCA)
B58: Sistema de Amortização PRICE | P58: Sistema de Amortização SAC
B59: Crédito Com Garantia de Imóvel - CGI - Parcela Fixa - Apartir de 1,09% a.m | P59: Financiamento Imobiliário - FI - Parcela Fixa de 1,29% a.m
B60: Financiamento Imobiliário - FI - Parcela Fixa de a partir de 1,09% a.m | P60: Financiamento Imobiliário - FI - Parcela Pós Fixado de 1,29% a.m
B61: Financiamento Imobiliário - FI - Parcela Pós de a partir de 0,99% a.m + IPCA | P61: Terreno Com Construção Concluída - TCC - Parcel Fixa - 1,29% a.m
B62: Terreno Com Construção Concluída - TCC - Apartir de Parcel Fixa - 1,09% a.m

Sheet Cálculos_Aquisição_SAC_Fixa
C2: Produto | H2: Tipo Imóvel
C3: Financiamento Imobiliário - FI | H3: Apartamento
C5: Valor do Crédito Bruto | F5: Valor Estimado do Imóvel | H5: LTV | I5: Prazo | J5: Sistema Amortização
C6: 125000 | F6: 300000 | H6: =IFERROR(C6/F6,"") -> 0.41666667 | I6: 180 | J6: SAC FIXA
C8: Cliente | H8: Nascimento | J8: Renda Necessária
C9: < Insira dados do cleinte mais velho> | H9: =T39 -> 29586 | J9: =J38*3.333333333 -> 7825.6481
C12: Valores da Operação - Aproximados | J12: %
C13: Valor Principal do Crédito | I13: =C6 -> 125000 | J13: ---
C14: Valor Estimado do Valor do Imóvel | I14: =F6 -> 300000
C15: Valor Total das Despesas acessórias | I15: 3000 | J15: =I15/I13 -> 0.024
C16: Valor Total do IOF no ato da liberação do Crédito (Sem IOF para operaçõees contratadas até 3 de julho de 2020) | I16: 0 | J16: =I16/I13 -> 0
C17: Valor Liquido a ser Liberado ao Emitente ou Vendedor | I17: =I13-I15-I16 -> 122000 | J17: =I17/I13 -> 0.976
C18: Prazo da Operação | I18: =I6 -> 180
C19: Taxa Efetiva - Anual | I19: =EFFECT(I21,I18/12) -> 0.16649869
C20: Taxa Efetiva - Mensal | I20: 0.0129
C21: Taxa Nominal - Anual | I21: =I22*12 -> 0.1548
C22: Taxa Nominal - Mensal | I22: =I20 -> 0.0129
C23: Sistema de Amortização | I23: =J6 -> SAC FIXA
C24: Data de Vencimento da Primeira Prestação | I24: =TODAY() -> 46058
C25: Data de Vencimento da Última Prestação | I25: =VLOOKUP(I18,A36:B307,2,0) -> 51537
C26: Valor da Prestação (Amortização + Juros) | I26: =$G$38 -> 2306.9444 | Z26: Controles de despesas
C27: Valor do Prêmio de Seguro MIP (Morte e Invalidez Permanente) | I27: =$H$38 -> 28.75 | Z27: TRUE
C28: Valor do Prêmio de Seguro DFI (Danos Físicos ao Imóvel) | I28: =$I$38 -> 12 | Z28: TRUE
C29: Valor Total da Prestação mensal | I29: =I26+I27+I28 -> 2347.6944 | Z29: TRUE
C30: CET - Custo Efetitvo Total | I30: =ROUNDUP((IRR(J37:J278,0)+1)^12-1,9) -> 0.2181324
Z32: 3 | AA32: Parcelas
Z33: 2 | AA33: Amortização
Z35: 1 | AA35: Saldo
A36: Parc | B36: Vencimento | C36: Saldo Inicial | D36: Juros | E36: Saldo Atualizado | F36: Amortização | G36: Prestação Mensal | H36: MIP | I36: DFI | J36: Prestação Mensal Total | K36: Saldo Devedor | N36: Formulas de Cálculo IOF | T36: Formulas de Cálculo Idade | AA36: 3 | AB36: =IF(AA36=1,"Evolução Saldo SAC x Price",IF(AA36=2,"Evolução Amortização SAC x Price","Evolução Parcelas SAC x Price")) -> Evolução Parcelas SAC x Price | AC36: =VLOOKUP(AA36,Z32:AA35,2,0) -> Parcelas
A37: 0 | B37: =I24 -> 46058 | C37: =I13 -> 125000 | J37: =I17*-1 -> -122000 | K37: =C37 -> 125000
A38: =IF(AND(A37=0,A37<$I$18),A37+1,0) -> 1 | B38: =IFERROR(IF(A38<=$I$18,DATE(YEAR(B37),MONTH(B37)+1,DAY(B37)),"-"),"") -> 46086 | C38: =IF(A38="","",K37) -> 125000 | D38: =IFERROR(ROUNDUP(C38*$I$20,2),"") -> 1612.5 | E38: =IFERROR(C38+D38,"") -> 126612.5 | F38: =IF(A38="","",$C$38/$I$18) -> 694.44444 | G38: =IF(A38="","",D38+F38) -> 2306.9444 | H38: =IFERROR($V$39*$C38,"") -> 28.75 | I38: =IF(A38="","",IF(K37="","",IF(K37=0,"",$W$39*$I$14))) -> 12 | J38: =IFERROR(SUM(I38+H38+G38),"") -> 2347.6944 | K38: =IF(A38="","",C38-F38) -> 124305.56 | O38: Calculo IOF | S38: Part | T38: Faixa Idade | U38: Idade | V38: Alicota | W38: DFI | X38: % de Comp. Renda | AA38: Parc | AB38: =IF($AA$36=1,VLOOKUP(AA38,$AE$38:$AK$218,6,0),IF($AA$36=2,VLOOKUP(AA38,$AE$38:$AK$218,4,0),VLOOKUP(AA38,$AE$38:$AK$218,2,0))) -> Parcela PRICE | AC38: =IF($AA$36=1,VLOOKUP(AA38,$AE$38:$AK$218,7,0),IF($AA$36=2,VLOOKUP(AA38,$AE$38:$AK$218,5,0),VLOOKUP(AA38,$AE$38:$AK$218,3,0))) -> Parcela SAC | AE38: Parc | AF38: Parcela PRICE | AG38: Parcela SAC | AH38: Amort. PRICE | AI38: Amort. SAC | AJ38: Saldo PRICE | AK38: Saldo SAC
A39: =IF(IF(AND(A38>0,A38<$I$18),A38+1,0)=0,"",IF(AND(A38>0,A38<$I$18),A38+1,0)) -> 2 | B39: =IFERROR(IF(A39<=$I$18,DATE(YEAR($B$38),MONTH($B$38)+A38,DAY($B$38)),"-"),"") -> 46117 | C39: =IF(A39="","",K38) -> 124305.56 | D39: =IFERROR(ROUNDUP(C39*$I$20,2),"") -> 1603.55 | E39: =IFERROR(C39+D39,"") -> 125909.11 | F39: =IF(A39="","",$C$38/$I$18) -> 694.44444 | G39: =IF(A39="","",D39+F39) -> 2297.9944 | H39: =IFERROR($V$39*$C39,"") -> 28.590278 | I39: =IF(A39="","",IF(K38="","",IF(K38=0,"",$W$39*$I$14))) -> 12 | J39: =IFERROR(SUM(I39+H39+G39),"") -> 2338.5847 | K39: =IF(A39="","",C39-F39) -> 123611.11 | N39: Acima de 12meses | O39: 0.03 | P39: =SUM(O55:O250) -> 3500 | Q39: =SUM(P39:P41) -> 4157.97 | S39: 1° Part | T39: =[1]Capa!P6 -> 29586 | U39: =IF($T$39="","",INT((TODAY())-$T$39)/365.25) -> 45.097878 | V39: =IF(AND(U39>=S48,U39<S49),U48,IF(AND(U39>=S49,U39<S50),U49,IF(AND(U39>=S50,U39<S51),U50,IF(AND(U39>=S51,U39<S52),U51,IF(AND(U39>=S52,U39<S53),U52,IF(AND(U39>=S53,U39<S54),U53,IF(AND(U39>=S54,U39<S55),U54,IF(AND(U39>=S55,U39<S56),U55,IF(AND(U39>=S56,U39<T56),U56,""))))))))) -> 0.00023 | W39: 4e-05 | AA39: =A38 -> 1 | AB39: =IF($AA$36=1,VLOOKUP(AA39,$AE$38:$AK$218,6,0),IF($AA$36=2,VLOOKUP(AA39,$AE$38:$AK$218,4,0),VLOOKUP(AA39,$AE$38:$AK$218,2,0))) -> 16352.11 | AC39: =IF($AA$36=1,VLOOKUP(AA39,$AE$38:$AK$278,7,0),IF($AA$36=2,VLOOKUP(AA39,$AE$38:$AK$278,5,0),VLOOKUP(AA39,$AE$38:$AK$278,3,0))) -> 2347.6944 | AE39: =AA39 -> 1 | AF39: =IFERROR(VLOOKUP(AE39,[1]Cálculos_PRICE!$A$32:$K$212,10,0),"") -> 16352.11 | AG39: =IFERROR(VLOOKUP(AE39,Cálculos_Aquisição_SAC_Fixa!A37:K310,10,0),"") -> 2347.6944 | AH39: =IFERROR(VLOOKUP(AE39,[1]Cálculos_PRICE!$A$32:$K$212,6,0),"") -> 1104.2104 | AI39: =IFERROR(VLOOKUP(AE39,Cálculos_Aquisição_SAC_Fixa!A37:K310,6,0),"") -> 694.44444 | AJ39: =IFERROR(VLOOKUP(AE39,[1]Cálculos_PRICE!$A$32:$K$240,11,0),"") -> 998895.79 | AK39: =IFERROR(VLOOKUP(AE39,Cálculos_Aquisição_SAC_Fixa!A37:K310,11,0),"") -> 124305.56
A40: =IF(IF(AND(A39>0,A39<$I$18),A39+1,0)=0,"",IF(AND(A39>0,A39<$I$18),A39+1,0)) -> 3 | B40: =IFERROR(IF(A40<=$I$18,DATE(YEAR($B$38),MONTH($B$38)+A39,DAY($B$38)),"-"),"") -> 46147 | C40: =IF(A40="","",K39) -> 123611.11 | D40: =IFERROR(ROUNDUP(C40*$I$20,2),"") -> 1594.59 | E40: =IFERROR(C40+D40,"") -> 125205.7 | F40: =IF(A40="","",$C$38/$I$18) -> 694.44444 | G40: =IF(A40="","",D40+F40) -> 2289.0344 | H40: =IFERROR($V$39*$C40,"") -> 28.430556 | I40: =IF(A40="","",IF(K39="","",IF(K39=0,"",$W$39*$I$14))) -> 12 | J40: =IFERROR(SUM(I40+H40+G40),"") -> 2329.465 | K40: =IF(A40="","",C40-F40) -> 122916.67 | N40: Valor Financiado | O40: 0.0038 | P40: =ROUNDUP(O40*$C$37,2) -> 475 | S40: 2° Part | AA40: =A39 -> 2 | AB40: =IF($AA$36=1,VLOOKUP(AA40,$AE$38:$AK$218,6,0),IF($AA$36=2,VLOOKUP(AA40,$AE$38:$AK$218,4,0),VLOOKUP(AA40,$AE$38:$AK$218,2,0))) -> 16351.865 | AC40: =IF($AA$36=1,VLOOKUP(AA40,$AE$38:$AK$278,7,0),IF($AA$36=2,VLOOKUP(AA40,$AE$38:$AK$278,5,0),VLOOKUP(AA40,$AE$38:$AK$278,3,0))) -> 2338.5847 | AE40: =AA40 -> 2 | AF40: =IFERROR(VLOOKUP(AE40,[1]Cálculos_PRICE!$A$32:$K$212,10,0),"") -> 16351.865 | AG40: =IFERROR(VLOOKUP(AE40,Cálculos_Aquisição_SAC_Fixa!A38:K311,10,0),"") -> 2338.5847 | AH40: =IFERROR(VLOOKUP(AE40,[1]Cálculos_PRICE!$A$32:$K$212,6,0),"") -> 1120.7736 | AI40: =IFERROR(VLOOKUP(AE40,Cálculos_Aquisição_SAC_Fixa!A38:K311,6,0),"") -> 694.44444 | AJ40: =IFERROR(VLOOKUP(AE40,[1]Cálculos_PRICE!$A$32:$K$240,11,0),"") -> 997775.02 | AK40: =IFERROR(VLOOKUP(AE40,Cálculos_Aquisição_SAC_Fixa!A38:K311,11,0),"") -> 123611.11
A41: =IF(IF(AND(A40>0,A40<$I$18),A40+1,0)=0,"",IF(AND(A40>0,A40<$I$18),A40+1,0)) -> 4 | B41: =IFERROR(IF(A41<=$I$18,DATE(YEAR($B$38),MONTH($B$38)+A40,DAY($B$38)),"-"),"") -> 46178 | C41: =IF(A41="","",K40) -> 122916.67 | D41: =IFERROR(ROUNDUP(C41*$I$20,2),"") -> 1585.63 | E41: =IFERROR(C41+D41,"") -> 124502.3 | F41: =IF(A41="","",$C$38/$I$18) -> 694.44444 | G41: =IF(A41="","",D41+F41) -> 2280.0744 | H41: =IFERROR($V$39*$C41,"") -> 28.270833 | I41: =IF(A41="","",IF(K40="","",IF(K40=0,"",$W$39*$I$14))) -> 12 | J41: =IFERROR(SUM(I41+H41+G41),"") -> 2320.3453 | K41: =IF(A41="","",C41-F41) -> 122222.22 | N41: Até 12 meses | O41: 0.0001118 | P41: =SUM(O43:O54) -> 182.97 | S41: 3° Part | AA41: =A40 -> 3 | AB41: =IF($AA$36=1,VLOOKUP(AA41,$AE$38:$AK$218,6,0),IF($AA$36=2,VLOOKUP(AA41,$AE$38:$AK$218,4,0),VLOOKUP(AA41,$AE$38:$AK$218,2,0))) -> 16351.616 | AC41: =IF($AA$36=1,VLOOKUP(AA41,$AE$38:$AK$278,7,0),IF($AA$36=2,VLOOKUP(AA41,$AE$38:$AK$278,5,0),VLOOKUP(AA41,$AE$38:$AK$278,3,0))) -> 2329.465 | AE41: =AA41 -> 3 | AF41: =IFERROR(VLOOKUP(AE41,[1]Cálculos_PRICE!$A$32:$K$212,10,0),"") -> 16351.616 | AG41: =IFERROR(VLOOKUP(AE41,Cálculos_Aquisição_SAC_Fixa!A39:K312,10,0),"") -> 2329.465 | AH41: =IFERROR(VLOOKUP(AE41,[1]Cálculos_PRICE!$A$32:$K$212,6,0),"") -> 1137.5852 | AI41: =IFERROR(VLOOKUP(AE41,Cálculos_Aquisição_SAC_Fixa!A39:K312,6,0),"") -> 694.44444 | AJ41: =IFERROR(VLOOKUP(AE41,[1]Cálculos_PRICE!$A$32:$K$240,11,0),"") -> 996637.43 | AK41: =IFERROR(VLOOKUP(AE41,Cálculos_Aquisição_SAC_Fixa!A39:K312,11,0),"") -> 122916.67
A42: =IF(IF(AND(A41>0,A41<$I$18),A41+1,0)=0,"",IF(AND(A41>0,A41<$I$18),A41+1,0)) -> 5 | B42: =IFERROR(IF(A42<=$I$18,DATE(YEAR($B$38),MONTH($B$38)+A41,DAY($B$38)),"-"),"") -> 46208 | C42: =IF(A42="","",K41) -> 122222.22 | D42: =IFERROR(ROUNDUP(C42*$I$20,2),"") -> 1576.67 | E42: =IFERROR(C42+D42,"") -> 123798.89 | F42: =IF(A42="","",$C$38/$I$18) -> 694.44444 | G42: =IF(A42="","",D42+F42) -> 2271.1144 | H42: =IFERROR($V$39*$C42,"") -> 28.111111 | I42: =IF(A42="","",IF(K41="","",IF(K41=0,"",$W$39*$I$14))) -> 12 | J42: =IFERROR(SUM(I42+H42+G42),"") -> 2311.2256 | K42: =IF(A42="","",C42-F42) -> 121527.78 | O42: IOF DIÁRIO | P42: DIAS | Q42: DIAS_SOMA | S42: 4° Part | AA42: =A41 -> 4 | AB42: =IF($AA$36=1,VLOOKUP(AA42,$AE$38:$AK$218,6,0),IF($AA$36=2,VLOOKUP(AA42,$AE$38:$AK$218,4,0),VLOOKUP(AA42,$AE$38:$AK$218,2,0))) -> 16351.363 | AC42: =IF($AA$36=1,VLOOKUP(AA42,$AE$38:$AK$278,7,0),IF($AA$36=2,VLOOKUP(AA42,$AE$38:$AK$278,5,0),VLOOKUP(AA42,$AE$38:$AK$278,3,0))) -> 2320.3453 | AE42: =AA42 -> 4 | AF42: =IFERROR(VLOOKUP(AE42,[1]Cálculos_PRICE!$A$32:$K$212,10,0),"") -> 16351.363 | AG42: =IFERROR(VLOOKUP(AE42,Cálculos_Aquisição_SAC_Fixa!A40:K313,10,0),"") -> 2320.3453 | AH42: =IFERROR(VLOOKUP(AE42,[1]Cálculos_PRICE!$A$32:$K$212,6,0),"") -> 1154.6489 | AI42: =IFERROR(VLOOKUP(AE42,Cálculos_Aquisição_SAC_Fixa!A40:K313,6,0),"") -> 694.44444 | AJ42: =IFERROR(VLOOKUP(AE42,[1]Cálculos_PRICE!$A$32:$K$240,11,0),"") -> 995482.78 | AK42: =IFERROR(VLOOKUP(AE42,Cálculos_Aquisição_SAC_Fixa!A40:K313,11,0),"") -> 122222.22
A43: =IF(IF(AND(A42>0,A42<$I$18),A42+1,0)=0,"",IF(AND(A42>0,A42<$I$18),A42+1,0)) -> 6 | B43: =IFERROR(IF(A43<=$I$18,DATE(YEAR($B$38),MONTH($B$38)+A42,DAY($B$38)),"-"),"") -> 46239 | C43: =IF(A43="","",K42) -> 121527.78 | D43: =IFERROR(ROUNDUP(C43*$I$20,2),"") -> 1567.71 | E43: =IFERROR(C43+D43,"") -> 123095.49 | F43: =IF(A43="","",$C$38/$I$18) -> 694.44444 | G43: =IF(A43="","",D43+F43) -> 2262.1544 | H43: =IFERROR($V$39*$C43,"") -> 27.951389 | I43: =IF(A43="","",IF(K42="","",IF(K42=0,"",$W$39*$I$14))) -> 12 | J43: =IFERROR(SUM(I43+H43+G43),"") -> 2302.1058 | K43: =IF(A43="","",C43-F43) -> 120833.33 | O43: =ROUNDUP(F38*$O$41*Q43,2) -> 2.18 | P43: =IF($A38<=$I$18,B38-B37,) -> 28 | Q43: =IF($A38<=$I$18,$B38-$B$37,) -> 28 | S43: 5° Part | AA43: =A42 -> 5 | AB43: =IF($AA$36=1,VLOOKUP(AA43,$AE$38:$AK$218,6,0),IF($AA$36=2,VLOOKUP(AA43,$AE$38:$AK$218,4,0),VLOOKUP(AA43,$AE$38:$AK$218,2,0))) -> 16351.106 | AC43: =IF($AA$36=1,VLOOKUP(AA43,$AE$38:$AK$278,7,0),IF($AA$36=2,VLOOKUP(AA43,$AE$38:$AK$278,5,0),VLOOKUP(AA43,$AE$38:$AK$278,3,0))) -> 2311.2256 | AE43: =AA43 -> 5 | AF43: =IFERROR(VLOOKUP(AE43,[1]Cálculos_PRICE!$A$32:$K$212,10,0),"") -> 16351.106 | AG43: =IFERROR(VLOOKUP(AE43,Cálculos_Aquisição_SAC_Fixa!A41:K314,10,0),"") -> 2311.2256 | AH43: =IFERROR(VLOOKUP(AE43,[1]Cálculos_PRICE!$A$32:$K$212,6,0),"") -> 1171.9687 | AI43: =IFERROR(VLOOKUP(AE43,Cálculos_Aquisição_SAC_Fixa!A41:K314,6,0),"") -> 694.44444 | AJ43: =IFERROR(VLOOKUP(AE43,[1]Cálculos_PRICE!$A$32:$K$240,11,0),"") -> 994310.81 | AK43: =IFERROR(VLOOKUP(AE43,Cálculos_Aquisição_SAC_Fixa!A41:K314,11,0),"") -> 121527.78
A44: =IF(IF(AND(A43>0,A43<$I$18),A43+1,0)=0,"",IF(AND(A43>0,A43<$I$18),A43+1,0)) -> 7 | B44: =IFERROR(IF(A44<=$I$18,DATE(YEAR($B$38),MONTH($B$38)+A43,DAY($B$38)),"-"),"") -> 46270 | C44: =IF(A44="","",K43) -> 120833.33 | D44: =IFERROR(ROUNDUP(C44*$I$20,2),"") -> 1558.75 | E44: =IFERROR(C44+D44,"") -> 122392.08 | F44: =IF(A44="","",$C$38/$I$18) -> 694.44444 | G44: =IF(A44="","",D44+F44) -> 2253.1944 | H44: =IFERROR($V$39*$C44,"") -> 27.791667 | I44: =IF(A44="","",IF(K43="","",IF(K43=0,"",$W$39*$I$14))) -> 12 | J44: =IFERROR(SUM(I44+H44+G44),"") -> 2292.9861 | K44: =IF(A44="","",C44-F44) -> 120138.89 | O44: =ROUNDUP(F39*$O$41*Q44,2) -> 4.59 | P44: =IF($A39<=$I$18,B39-B38,) -> 31 | Q44: =IF($A39<=$I$18,$B39-$B$37,) -> 59 | S44: 6° Part | AA44: =A43 -> 6 | AB44: =IF($AA$36=1,VLOOKUP(AA44,$AE$38:$AK$218,6,0),IF($AA$36=2,VLOOKUP(AA44,$AE$38:$AK$218,4,0),VLOOKUP(AA44,$AE$38:$AK$218,2,0))) -> 16350.845 | AC44: =IF($AA$36=1,VLOOKUP(AA44,$AE$38:$AK$278,7,0),IF($AA$36=2,VLOOKUP(AA44,$AE$38:$AK$278,5,0),VLOOKUP(AA44,$AE$38:$AK$278,3,0))) -> 2302.1058 | AE44: =AA44 -> 6 | AF44: =IFERROR(VLOOKUP(AE44,[1]Cálculos_PRICE!$A$32:$K$212,10,0),"") -> 16350.845 | AG44: =IFERROR(VLOOKUP(AE44,Cálculos_Aquisição_SAC_Fixa!A42:K315,10,0),"") -> 2302.1058 | AH44: =IFERROR(VLOOKUP(AE44,[1]Cálculos_PRICE!$A$32:$K$212,6,0),"") -> 1189.5482 | AI44: =IFERROR(VLOOKUP(AE44,Cálculos_Aquisição_SAC_Fixa!A42:K315,6,0),"") -> 694.44444 | AJ44: =IFERROR(VLOOKUP(AE44,[1]Cálculos_PRICE!$A$32:$K$240,11,0),"") -> 993121.27 | AK44: =IFERROR(VLOOKUP(AE44,Cálculos_Aquisição_SAC_Fixa!A42:K315,11,0),"") -> 120833.33
A45: =IF(IF(AND(A44>0,A44<$I$18),A44+1,0)=0,"",IF(AND(A44>0,A44<$I$18),A44+1,0)) -> 8 | B45: =IFERROR(IF(A45<=$I$18,DATE(YEAR($B$38),MONTH($B$38)+A44,DAY($B$38)),"-"),"") -> 46300 | C45: =IF(A45="","",K44) -> 120138.89 | D45: =IFERROR(ROUNDUP(C45*$I$20,2),"") -> 1549.8 | E45: =IFERROR(C45+D45,"") -> 121688.69 | F45: =IF(A45="","",$C$38/$I$18) -> 694.44444 | G45: =IF(A45="","",D45+F45) -> 2244.2444 | H45: =IFERROR($V$39*$C45,"") -> 27.631944 | I45: =IF(A45="","",IF(K44="","",IF(K44=0,"",$W$39*$I$14))) -> 12 | J45: =IFERROR(SUM(I45+H45+G45),"") -> 2283.8764 | K45: =IF(A45="","",C45-F45) -> 119444.44 | O45: =ROUNDUP(F40*$O$41*Q45,2) -> 6.91 | P45: =IF($A40<=$I$18,B40-B39,) -> 30 | Q45: =IF($A40<=$I$18,$B40-$B$37,) -> 89 | S45: 7° Part | AA45: =A44 -> 7 | AB45: =IF($AA$36=1,VLOOKUP(AA45,$AE$38:$AK$218,6,0),IF($AA$36=2,VLOOKUP(AA45,$AE$38:$AK$218,4,0),VLOOKUP(AA45,$AE$38:$AK$218,2,0))) -> 16350.581 | AC45: =IF($AA$36=1,VLOOKUP(AA45,$AE$38:$AK$278,7,0),IF($AA$36=2,VLOOKUP(AA45,$AE$38:$AK$278,5,0),VLOOKUP(AA45,$AE$38:$AK$278,3,0))) -> 2292.9861 | AE45: =AA45 -> 7 | AF45: =IFERROR(VLOOKUP(AE45,[1]Cálculos_PRICE!$A$32:$K$212,10,0),"") -> 16350.581 | AG45: =IFERROR(VLOOKUP(AE45,Cálculos_Aquisição_SAC_Fixa!A43:K316,10,0),"") -> 2292.9861 | AH45: =IFERROR(VLOOKUP(AE45,[1]Cálculos_PRICE!$A$32:$K$212,6,0),"") -> 1207.3914 | AI45: =IFERROR(VLOOKUP(AE45,Cálculos_Aquisição_SAC_Fixa!A43:K316,6,0),"") -> 694.44444 | AJ45: =IFERROR(VLOOKUP(AE45,[1]Cálculos_PRICE!$A$32:$K$240,11,0),"") -> 991913.87 | AK45: =IFERROR(VLOOKUP(AE45,Cálculos_Aquisição_SAC_Fixa!A43:K316,11,0),"") -> 120138.89
A46: =IF(IF(AND(A45>0,A45<$I$18),A45+1,0)=0,"",IF(AND(A45>0,A45<$I$18),A45+1,0)) -> 9 | B46: =IFERROR(IF(A46<=$I$18,DATE(YEAR($B$38),MONTH($B$38)+A45,DAY($B$38)),"-"),"") -> 46331 | C46: =IF(A46="","",K45) -> 119444.44 | D46: =IFERROR(ROUNDUP(C46*$I$20,2),"") -> 1540.84 | E46: =IFERROR(C46+D46,"") -> 120985.28 | F46: =IF(A46="","",$C$38/$I$18) -> 694.44444 | G46: =IF(A46="","",D46+F46) -> 2235.2844 | H46: =IFERROR($V$39*$C46,"") -> 27.472222 | I46: =IF(A46="","",IF(K45="","",IF(K45=0,"",$W$39*$I$14))) -> 12 | J46: =IFERROR(SUM(I46+H46+G46),"") -> 2274.7567 | K46: =IF(A46="","",C46-F46) -> 118750 | O46: =ROUNDUP(F41*$O$41*Q46,2) -> 9.32 | P46: =IF($A41<=$I$18,B41-B40,) -> 31 | Q46: =IF($A41<=$I$18,$B41-$B$37,) -> 120 | S46: 8° Part | AA46: =A45 -> 8 | AB46: =IF($AA$36=1,VLOOKUP(AA46,$AE$38:$AK$218,6,0),IF($AA$36=2,VLOOKUP(AA46,$AE$38:$AK$218,4,0),VLOOKUP(AA46,$AE$38:$AK$218,2,0))) -> 16350.312 | AC46: =IF($AA$36=1,VLOOKUP(AA46,$AE$38:$AK$278,7,0),IF($AA$36=2,VLOOKUP(AA46,$AE$38:$AK$278,5,0),VLOOKUP(AA46,$AE$38:$AK$278,3,0))) -> 2283.8764 | AE46: =AA46 -> 8 | AF46: =IFERROR(VLOOKUP(AE46,[1]Cálculos_PRICE!$A$32:$K$212,10,0),"") -> 16350.312 | AG46: =IFERROR(VLOOKUP(AE46,Cálculos_Aquisição_SAC_Fixa!A44:K317,10,0),"") -> 2283.8764 | AH46: =IFERROR(VLOOKUP(AE46,[1]Cálculos_PRICE!$A$32:$K$212,6,0),"") -> 1225.5023 | AI46: =IFERROR(VLOOKUP(AE46,Cálculos_Aquisição_SAC_Fixa!A44:K317,6,0),"") -> 694.44444 | AJ46: =IFERROR(VLOOKUP(AE46,[1]Cálculos_PRICE!$A$32:$K$240,11,0),"") -> 990688.37 | AK46: =IFERROR(VLOOKUP(AE46,Cálculos_Aquisição_SAC_Fixa!A44:K317,11,0),"") -> 119444.44
A47: =IF(IF(AND(A46>0,A46<$I$18),A46+1,0)=0,"",IF(AND(A46>0,A46<$I$18),A46+1,0)) -> 10 | B47: =IFERROR(IF(A47<=$I$18,DATE(YEAR($B$38),MONTH($B$38)+A46,DAY($B$38)),"-"),"") -> 46361 | C47: =IF(A47="","",K46) -> 118750 | D47: =IFERROR(ROUNDUP(C47*$I$20,2),"") -> 1531.88 | E47: =IFERROR(C47+D47,"") -> 120281.88 | F47: =IF(A47="","",$C$38/$I$18) -> 694.44444 | G47: =IF(A47="","",D47+F47) -> 2226.3244 | H47: =IFERROR($V$39*$C47,"") -> 27.3125 | I47: =IF(A47="","",IF(K46="","",IF(K46=0,"",$W$39*$I$14))) -> 12 | J47: =IFERROR(SUM(I47+H47+G47),"") -> 2265.6369 | K47: =IF(A47="","",C47-F47) -> 118055.56 | O47: =ROUNDUP(F42*$O$41*Q47,2) -> 11.65 | P47: =IF($A42<=$I$18,B42-B41,) -> 30 | Q47: =IF($A42<=$I$18,$B42-$B$37,) -> 150 | S47: Faixa Idade | U47: Alicota | V47: DFI | AA47: =A46 -> 9 | AB47: =IF($AA$36=1,VLOOKUP(AA47,$AE$38:$AK$218,6,0),IF($AA$36=2,VLOOKUP(AA47,$AE$38:$AK$218,4,0),VLOOKUP(AA47,$AE$38:$AK$218,2,0))) -> 16350.039 | AC47: =IF($AA$36=1,VLOOKUP(AA47,$AE$38:$AK$278,7,0),IF($AA$36=2,VLOOKUP(AA47,$AE$38:$AK$278,5,0),VLOOKUP(AA47,$AE$38:$AK$278,3,0))) -> 2274.7567 | AE47: =AA47 -> 9 | AF47: =IFERROR(VLOOKUP(AE47,[1]Cálculos_PRICE!$A$32:$K$212,10,0),"") -> 16350.039 | AG47: =IFERROR(VLOOKUP(AE47,Cálculos_Aquisição_SAC_Fixa!A45:K318,10,0),"") -> 2274.7567 | AH47: =IFERROR(VLOOKUP(AE47,[1]Cálculos_PRICE!$A$32:$K$212,6,0),"") -> 1243.8848 | AI47: =IFERROR(VLOOKUP(AE47,Cálculos_Aquisição_SAC_Fixa!A45:K318,6,0),"") -> 694.44444 | AJ47: =IFERROR(VLOOKUP(AE47,[1]Cálculos_PRICE!$A$32:$K$240,11,0),"") -> 989444.49 | AK47: =IFERROR(VLOOKUP(AE47,Cálculos_Aquisição_SAC_Fixa!A45:K318,11,0),"") -> 118750
...
